SUBJECT: Error in IQAMA_JOB_AHJ_DOT-CARE on AHQ-AI-02
TIME: 2025-05-01 15:42:30
HOST: AHQ-AI-02
SYSTEM: Windows 2019Server
PYTHON: 3.12.8

==================================================

An error occurred in the IQAMA_JOB_AHJ_DOT-CARE job on AHQ-AI-02 at 2025-05-01 15:42:30.

Error details:
('Connection aborted.', ConnectionResetError(10054, 'An existing connection was forcibly closed by the remote host', None, 10054, None))

Traceback (most recent call last):
  File "C:\Data-Science\Deployment\Eligibilty_api_schedule\myenv\Lib\site-packages\urllib3\connectionpool.py", line 787, in urlopen
    response = self._make_request(
               ^^^^^^^^^^^^^^^^^^^
  File "C:\Data-Science\Deployment\Eligibilty_api_schedule\myenv\Lib\site-packages\urllib3\connectionpool.py", line 534, in _make_request
    response = conn.getresponse()
               ^^^^^^^^^^^^^^^^^^
  File "C:\Data-Science\Deployment\Eligibilty_api_schedule\myenv\Lib\site-packages\urllib3\connection.py", line 516, in getresponse
    httplib_response = super().getresponse()
                       ^^^^^^^^^^^^^^^^^^^^^
  File "C:\Users\ai-service\AppData\Local\Programs\Python\Python312\Lib\http\client.py", line 1428, in getresponse
    response.begin()
  File "C:\Users\ai-service\AppData\Local\Programs\Python\Python312\Lib\http\client.py", line 331, in begin
    version, status, reason = self._read_status()
                              ^^^^^^^^^^^^^^^^^^^
  File "C:\Users\ai-service\AppData\Local\Programs\Python\Python312\Lib\http\client.py", line 292, in _read_status
    line = str(self.fp.readline(_MAXLINE + 1), "iso-8859-1")
               ^^^^^^^^^^^^^^^^^^^^^^^^^^^^^^
  File "C:\Users\ai-service\AppData\Local\Programs\Python\Python312\Lib\socket.py", line 720, in readinto
    return self._sock.recv_into(b)
           ^^^^^^^^^^^^^^^^^^^^^^^
ConnectionResetError: [WinError 10054] An existing connection was forcibly closed by the remote host

During handling of the above exception, another exception occurred:

Traceback (most recent call last):
  File "C:\Data-Science\Deployment\Eligibilty_api_schedule\myenv\Lib\site-packages\requests\adapters.py", line 667, in send
    resp = conn.urlopen(
           ^^^^^^^^^^^^^
  File "C:\Data-Science\Deployment\Eligibilty_api_schedule\myenv\Lib\site-packages\urllib3\connectionpool.py", line 841, in urlopen
    retries = retries.increment(
              ^^^^^^^^^^^^^^^^^^
  File "C:\Data-Science\Deployment\Eligibilty_api_schedule\myenv\Lib\site-packages\urllib3\util\retry.py", line 474, in increment
    raise reraise(type(error), error, _stacktrace)
          ^^^^^^^^^^^^^^^^^^^^^^^^^^^^^^^^^^^^^^^^
  File "C:\Data-Science\Deployment\Eligibilty_api_schedule\myenv\Lib\site-packages\urllib3\util\util.py", line 38, in reraise
    raise value.with_traceback(tb)
  File "C:\Data-Science\Deployment\Eligibilty_api_schedule\myenv\Lib\site-packages\urllib3\connectionpool.py", line 787, in urlopen
    response = self._make_request(
               ^^^^^^^^^^^^^^^^^^^
  File "C:\Data-Science\Deployment\Eligibilty_api_schedule\myenv\Lib\site-packages\urllib3\connectionpool.py", line 534, in _make_request
    response = conn.getresponse()
               ^^^^^^^^^^^^^^^^^^
  File "C:\Data-Science\Deployment\Eligibilty_api_schedule\myenv\Lib\site-packages\urllib3\connection.py", line 516, in getresponse
    httplib_response = super().getresponse()
                       ^^^^^^^^^^^^^^^^^^^^^
  File "C:\Users\ai-service\AppData\Local\Programs\Python\Python312\Lib\http\client.py", line 1428, in getresponse
    response.begin()
  File "C:\Users\ai-service\AppData\Local\Programs\Python\Python312\Lib\http\client.py", line 331, in begin
    version, status, reason = self._read_status()
                              ^^^^^^^^^^^^^^^^^^^
  File "C:\Users\ai-service\AppData\Local\Programs\Python\Python312\Lib\http\client.py", line 292, in _read_status
    line = str(self.fp.readline(_MAXLINE + 1), "iso-8859-1")
               ^^^^^^^^^^^^^^^^^^^^^^^^^^^^^^
  File "C:\Users\ai-service\AppData\Local\Programs\Python\Python312\Lib\socket.py", line 720, in readinto
    return self._sock.recv_into(b)
           ^^^^^^^^^^^^^^^^^^^^^^^
urllib3.exceptions.ProtocolError: ('Connection aborted.', ConnectionResetError(10054, 'An existing connection was forcibly closed by the remote host', None, 10054, None))

During handling of the above exception, another exception occurred:

Traceback (most recent call last):
  File "C:\Data-Science\Deployment\Eligibilty_api_schedule\eligibilty_api_schedule.py", line 70, in _eligibility_iqama_job
    result_df = Iqama_table(df_new)
                ^^^^^^^^^^^^^^^^^^^
  File "C:\Data-Science\Deployment\Eligibilty_api_schedule\src\utils.py", line 164, in Iqama_table
    eligibility_dict[int(iqama)] = Beneficiary_api(int(iqama))
                                   ^^^^^^^^^^^^^^^^^^^^^^^^^^^
  File "C:\Data-Science\Deployment\Eligibilty_api_schedule\src\utils.py", line 92, in Beneficiary_api
    response = requests.get(url)
               ^^^^^^^^^^^^^^^^^
  File "C:\Data-Science\Deployment\Eligibilty_api_schedule\myenv\Lib\site-packages\requests\api.py", line 73, in get
    return request("get", url, params=params, **kwargs)
           ^^^^^^^^^^^^^^^^^^^^^^^^^^^^^^^^^^^^^^^^^^^^
  File "C:\Data-Science\Deployment\Eligibilty_api_schedule\myenv\Lib\site-packages\requests\api.py", line 59, in request
    return session.request(method=method, url=url, **kwargs)
           ^^^^^^^^^^^^^^^^^^^^^^^^^^^^^^^^^^^^^^^^^^^^^^^^^
  File "C:\Data-Science\Deployment\Eligibilty_api_schedule\myenv\Lib\site-packages\requests\sessions.py", line 589, in request
    resp = self.send(prep, **send_kwargs)
           ^^^^^^^^^^^^^^^^^^^^^^^^^^^^^^
  File "C:\Data-Science\Deployment\Eligibilty_api_schedule\myenv\Lib\site-packages\requests\sessions.py", line 703, in send
    r = adapter.send(request, **kwargs)
        ^^^^^^^^^^^^^^^^^^^^^^^^^^^^^^^
  File "C:\Data-Science\Deployment\Eligibilty_api_schedule\myenv\Lib\site-packages\requests\adapters.py", line 682, in send
    raise ConnectionError(err, request=request)
requests.exceptions.ConnectionError: ('Connection aborted.', ConnectionResetError(10054, 'An existing connection was forcibly closed by the remote host', None, 10054, None))


Please check the scheduler.log file for more information.